Workbook

Sheet Product Catalog
A1: SageReasoning V3 — Revised Product Catalog (Half-Competitor Pricing)
A2: Prices = half of lowest competitor in each category. R5 (≥2× LLM cost) still satisfied for all products.
A4: Skill ID | B4: Display Name | C4: Tier | D4: Category | E4: New Price | F4: Old Price | G4: LLM Cost | H4: Margin per Call | I4: Margin % | J4: Mechanisms | K4: Pricing Rule
A5: sage-reason-quick | B5: sage-reason (quick) | C5: Tier 1 | D5: Infrastructure | E5: 0.18 | F5: 0.025 | G5: 0.0125 | H5: =E5-G5 | I5: =H5/E5 | J5: 3 | K5: ½ × Clearbit ($0.36)
A6: sage-reason-standard | B6: sage-reason (standard) | C6: Tier 1 | D6: Infrastructure | E6: 0.18 | F6: 0.041 | G6: 0.0205 | H6: =E6-G6 | I6: =H6/E6 | J6: 5 | K6: ½ × Clearbit ($0.36)
A7: sage-reason-deep | B7: sage-reason (deep) | C7: Tier 1 | D7: Infrastructure | E7: 0.18 | F7: 0.055 | G7: 0.0275 | H7: =E7-G7 | I7: =H7/E7 | J7: 6 | K7: ½ × Clearbit ($0.36)
A8: sage-score | B8: sage-score | C8: Tier 2 Core | D8: Core Evaluation | E8: 0.18 | F8: 0.033 | G8: 0.0165 | H8: =E8-G8 | I8: =H8/E8 | J8: 4 | K8: ½ × Clearbit ($0.36)
A9: sage-guard | B9: sage-guard | C9: Tier 2 Core | D9: Core Evaluation | E9: 0.0025 | F9: 0.001 | G9: 0.0005 | H9: =E9-G9 | I9: =H9/E9 | J9: 2 | K9: ½ × Guardrails AI ($0.005)
A10: sage-iterate | B10: sage-iterate (per iter) | C10: Tier 2 Core | D10: Core Evaluation | E10: 0.18 | F10: 0.033 | G10: 0.0165 | H10: =E10-G10 | I10: =H10/E10 | J10: 4 | K10: ½ × Clearbit ($0.36)
A11: sage-decide | B11: sage-decide | C11: Tier 2 Core | D11: Core Evaluation | E11: 0.18 | F11: 0.033 | G11: 0.0165 | H11: =E11-G11 | I11: =H11/E11 | J11: 3 | K11: ½ × Clearbit ($0.36)
A12: sage-audit | B12: sage-audit | C12: Tier 2 Core | D12: Core Evaluation | E12: 0.18 | F12: 0.033 | G12: 0.0165 | H12: =E12-G12 | I12: =H12/E12 | J12: 4 | K12: ½ × Clearbit ($0.36)
A13: sage-converse | B13: sage-converse | C13: Tier 2 Core | D13: Core Evaluation | E13: 0.18 | F13: 0.033 | G13: 0.0165 | H13: =E13-G13 | I13: =H13/E13 | J13: 3 | K13: ½ × Clearbit ($0.36)
A14: sage-scenario | B14: sage-scenario | C14: Tier 2 Core | D14: Core Evaluation | E14: 0.18 | F14: 0.066 | G14: 0.033 | H14: =E14-G14 | I14: =H14/E14 | J14: 3 | K14: ½ × Clearbit ($0.36)
A15: sage-reflect | B15: sage-reflect | C15: Tier 2 Core | D15: Core Evaluation | E15: 0.18 | F15: 0.033 | G15: 0.0165 | H15: =E15-G15 | I15: =H15/E15 | J15: 2 | K15: ½ × Clearbit ($0.36)
A16: sage-context | B16: sage-context | C16: Tier 2 Core | D16: Free Endpoint | E16: 0 | F16: 0 | G16: 0 | H16: 0 | I16: 0 | J16: 0 | K16: Free (no AI call)
A17: sage-diagnose | B17: sage-diagnose | C17: Tier 2 Core | D17: Assessment | E17: 0.5 | F17: 0.033 | G17: 0.0165 | H17: =E17-G17 | I17: =H17/E17 | J17: 3 | K17: ½ × Crystal Knows (est. $1)
A18: sage-profile | B18: sage-profile | C18: Tier 2 Core | D18: Assessment | E18: 0.5 | F18: 0.033 | G18: 0.0165 | H18: =E18-G18 | I18: =H18/E18 | J18: 4 | K18: ½ × Crystal Knows (est. $1)
A19: sage-premortem | B19: sage-premortem | C19: Tier 2 Marketplace | D19: Business Decision | E19: 0.18 | F19: 0.041 | G19: 0.0205 | H19: =E19-G19 | I19: =H19/E19 | J19: 5 | K19: ½ × Clearbit ($0.36)
A20: sage-negotiate | B20: sage-negotiate | C20: Tier 2 Marketplace | D20: Business Decision | E20: 0.18 | F20: 0.041 | G20: 0.0205 | H20: =E20-G20 | I20: =H20/E20 | J20: 5 | K20: ½ × Clearbit ($0.36)
A21: sage-invest | B21: sage-invest | C21: Tier 2 Marketplace | D21: Business Decision | E21: 0.18 | F21: 0.041 | G21: 0.0205 | H21: =E21-G21 | I21: =H21/E21 | J21: 5 | K21: ½ × Clearbit ($0.36)
A22: sage-pivot | B22: sage-pivot | C22: Tier 2 Marketplace | D22: Business Decision | E22: 0.18 | F22: 0.041 | G22: 0.0205 | H22: =E22-G22 | I22: =H22/E22 | J22: 5 | K22: ½ × Clearbit ($0.36)
A23: sage-retro | B23: sage-retro | C23: Tier 2 Marketplace | D23: Business Decision | E23: 0.18 | F23: 0.041 | G23: 0.0205 | H23: =E23-G23 | I23: =H23/E23 | J23: 5 | K23: ½ × Clearbit ($0.36)
A24: sage-align | B24: sage-align | C24: Tier 2 Marketplace | D24: Team & Org | E24: 0.18 | F24: 0.041 | G24: 0.0205 | H24: =E24-G24 | I24: =H24/E24 | J24: 5 | K24: ½ × Clearbit ($0.36)
A25: sage-resolve | B25: sage-resolve | C25: Tier 2 Marketplace | D25: Team & Org | E25: 0.18 | F25: 0.041 | G25: 0.0205 | H25: =E25-G25 | I25: =H25/E25 | J25: 5 | K25: ½ × Clearbit ($0.36)
A26: sage-coach | B26: sage-coach | C26: Tier 2 Marketplace | D26: Team & Org | E26: 0.18 | F26: 0.041 | G26: 0.0205 | H26: =E26-G26 | I26: =H26/E26 | J26: 5 | K26: ½ × Clearbit ($0.36)
A27: sage-identity | B27: sage-identity | C27: Tier 2 Marketplace | D27: Deep Analysis | E27: 0.18 | F27: 0.055 | G27: 0.0275 | H27: =E27-G27 | I27: =H27/E27 | J27: 6 | K27: ½ × Clearbit ($0.36)
A28: sage-govern | B28: sage-govern | C28: Tier 2 Marketplace | D28: Deep Analysis | E28: 0.18 | F28: 0.055 | G28: 0.0275 | H28: =E28-G28 | I28: =H28/E28 | J28: 6 | K28: ½ × Clearbit ($0.36)
... A33: sage-prioritise | B33: sage-prioritise | C33: Tier 2 Marketplace | D33: Utility | E33: 0.18 | F33: 0.025 | G33: 0.0125 | H33: =E33-G33 | I33: =H33/E33 | J33: 3 | K33: ½ × Clearbit ($0.36)
A35: CATALOG SUMMARY
A36: Total paid skills | B36: =COUNTIF(E5:E33,">0")
A37: Avg new price (paid skills) | B37: =AVERAGEIF(E5:E33,">0")
A38: Avg old price (paid skills) | B38: =AVERAGEIF(F5:F33,">0")
A39: Avg price increase | B39: =B37/B38-1
A40: Avg margin % (was 50% flat) | B40: =AVERAGEIF(I5:I33,">0")

Sheet Agent Usage Profiles
A1: Agent Usage Profiles — Revised Pricing (Half-Competitor Rule)
A2: Call volumes unchanged. Prices revised per half-competitor rule. Revenue = calls × new price.
B3: sage-guard for every decision, sage-score for flagged items | C3: Core evaluation suite for business decisions | D3: Governance + compliance + audit focus | E3: Coaching, identity, reflection focus | F3: Broad skill mix across categories
A4: Skill | B4: Reasoning Guard (High-Volume Gate) | C4: Decision Support (Standard Agent) | D4: Compliance Agent (Enterprise) | E4: Personal Coach (Consumer App) | F4: Full-Stack Agent (Power User) | G4: New Price | H4: LLM Cost
A5: TIER 1: INFRASTRUCTURE
A6: sage-reason-quick | B6: 0 | C6: 200 | D6: 100 | E6: 150 | F6: 300 | G6: 0.18 | H6: 0.0125
A7: sage-reason-standard | B7: 0 | C7: 500 | D7: 300 | E7: 200 | F7: 400 | G7: 0.18 | H7: 0.0205
A8: sage-reason-deep | B8: 0 | C8: 50 | D8: 100 | E8: 100 | F8: 200 | G8: 0.18 | H8: 0.0275
A9: TIER 2: CORE EVALUATION
A10: sage-guard | B10: 5000 | C10: 200 | D10: 1000 | E10: 100 | F10: 500 | G10: 0.0025 | H10: 0.0005
A11: sage-score | B11: 500 | C11: 300 | D11: 200 | E11: 100 | F11: 200 | G11: 0.18 | H11: 0.0165
A12: sage-iterate (× avg 2.5) | B12: 100 | C12: 200 | D12: 150 | E12: 300 | F12: 250 | G12: 0.18 | H12: 0.0165
A13: sage-decide | B13: 0 | C13: 200 | D13: 50 | E13: 50 | F13: 150 | G13: 0.18 | H13: 0.0165
A14: sage-audit | B14: 0 | C14: 50 | D14: 300 | E14: 0 | F14: 100 | G14: 0.18 | H14: 0.0165
A15: sage-converse | B15: 0 | C15: 0 | D15: 100 | E15: 50 | F15: 50 | G15: 0.18 | H15: 0.0165
A16: sage-scenario | B16: 0 | C16: 20 | D16: 0 | E16: 100 | F16: 50 | G16: 0.18 | H16: 0.033
A17: sage-reflect | B17: 0 | C17: 0 | D17: 0 | E17: 200 | F17: 100 | G17: 0.18 | H17: 0.0165
A18: sage-diagnose | B18: 0 | C18: 10 | D18: 20 | E18: 30 | F18: 20 | G18: 0.5 | H18: 0.0165
A19: sage-profile | B19: 0 | C19: 10 | D19: 20 | E19: 20 | F19: 15 | G19: 0.5 | H19: 0.0165
A20: TIER 2: MARKETPLACE
A21: sage-premortem | B21: 0 | C21: 100 | D21: 50 | E21: 0 | F21: 80 | G21: 0.18 | H21: 0.0205
A22: sage-negotiate | B22: 0 | C22: 80 | D22: 0 | E22: 0 | F22: 50 | G22: 0.18 | H22: 0.0205
A23: sage-invest | B23: 0 | C23: 50 | D23: 0 | E23: 0 | F23: 30 | G23: 0.18 | H23: 0.0205
A24: sage-pivot | B24: 0 | C24: 30 | D24: 0 | E24: 0 | F24: 20 | G24: 0.18 | H24: 0.0205
A25: sage-retro | B25: 0 | C25: 50 | D25: 30 | E25: 0 | F25: 40 | G25: 0.18 | H25: 0.0205
A26: sage-align | B26: 0 | C26: 30 | D26: 50 | E26: 0 | F26: 30 | G26: 0.18 | H26: 0.0205
A27: sage-resolve | B27: 0 | C27: 20 | D27: 30 | E27: 20 | F27: 20 | G27: 0.18 | H27: 0.0205
A28: sage-coach | B28: 0 | C28: 0 | D28: 0 | E28: 200 | F28: 30 | G28: 0.18 | H28: 0.0205
A29: sage-identity | B29: 0 | C29: 0 | D29: 0 | E29: 100 | F29: 20 | G29: 0.18 | H29: 0.0275
A30: sage-govern | B30: 0 | C30: 0 | D30: 200 | E30: 0 | F30: 30 | G30: 0.18 | H30: 0.0275
A31: sage-compliance | B31: 0 | C31: 0 | D31: 300 | E31: 0 | F31: 50 | G31: 0.18 | H31: 0.0205
A32: sage-moderate | B32: 0 | C32: 0 | D32: 200 | E32: 0 | F32: 100 | G32: 0.18 | H32: 0.0125
... A35: sage-prioritise | B35: 0 | C35: 100 | D35: 50 | E35: 50 | F35: 80 | G35: 0.18 | H35: 0.0125
A37: TOTAL CALLS / MONTH | B37: =B6+B7+B8+B10+B11+B12+B13+B14+B15+B16+B17+B18+B19+B21+B22+B23+B24+B25+B26+B27+B28+B29+B30+B31+B32+B33+B34+B35 | C37: =C6+C7+C8+C10+C11+C12+C13+C14+C15+C16+C17+C18+C19+C21+C22+C23+C24+C25+C26+C27+C28+C29+C30+C31+C32+C33+C34+C35 | D37: =D6+D7+D8+D10+D11+D12+D13+D14+D15+D16+D17+D18+D19+D21+D22+D23+D24+D25+D26+D27+D28+D29+D30+D31+D32+D33+D34+D35 | E37: =E6+E7+E8+E10+E11+E12+E13+E14+E15+E16+E17+E18+E19+E21+E22+E23+E24+E25+E26+E27+E28+E29+E30+E31+E32+E33+E34+E35 | F37: =F6+F7+F8+F10+F11+F12+F13+F14+F15+F16+F17+F18+F19+F21+F22+F23+F24+F25+F26+F27+F28+F29+F30+F31+F32+F33+F34+F35
A38: REVENUE / MONTH (per agent) | B38: =(B6*G6)+(B7*G7)+(B8*G8)+(B10*G10)+(B11*G11)+(B12*G12)+(B13*G13)+(B14*G14)+(B15*G15)+(B16*G16)+(B17*G17)+(B18*G18)+(B19*G19)+(B21*G21)+(B22*G22)+(B23*G23)+(B24*G24)+(B25*G25)+(B26*G26)+(B27*G27)+(B28*G28)+(B29*G29)+(B30*G30)+(B31*G31)+(B32*G32)+(B33*G33)+(B34*G34)+(B35*G35) | C38: =(C6*G6)+(C7*G7)+(C8*G8)+(C10*G10)+(C11*G11)+(C12*G12)+(C13*G13)+(C14*G14)+(C15*G15)+(C16*G16)+(C17*G17)+(C18*G18)+(C19*G19)+(C21*G21)+(C22*G22)+(C23*G23)+(C24*G24)+(C25*G25)+(C26*G26)+(C27*G27)+(C28*G28)+(C29*G29)+(C30*G30)+(C31*G31)+(C32*G32)+(C33*G33)+(C34*G34)+(C35*G35) | D38: =(D6*G6)+(D7*G7)+(D8*G8)+(D10*G10)+(D11*G11)+(D12*G12)+(D13*G13)+(D14*G14)+(D15*G15)+(D16*G16)+(D17*G17)+(D18*G18)+(D19*G19)+(D21*G21)+(D22*G22)+(D23*G23)+(D24*G24)+(D25*G25)+(D26*G26)+(D27*G27)+(D28*G28)+(D29*G29)+(D30*G30)+(D31*G31)+(D32*G32)+(D33*G33)+(D34*G34)+(D35*G35) | E38: =(E6*G6)+(E7*G7)+(E8*G8)+(E10*G10)+(E11*G11)+(E12*G12)+(E13*G13)+(E14*G14)+(E15*G15)+(E16*G16)+(E17*G17)+(E18*G18)+(E19*G19)+(E21*G21)+(E22*G22)+(E23*G23)+(E24*G24)+(E25*G25)+(E26*G26)+(E27*G27)+(E28*G28)+(E29*G29)+(E30*G30)+(E31*G31)+(E32*G32)+(E33*G33)+(E34*G34)+(E35*G35) | F38: =(F6*G6)+(F7*G7)+(F8*G8)+(F10*G10)+(F11*G11)+(F12*G12)+(F13*G13)+(F14*G14)+(F15*G15)+(F16*G16)+(F17*G17)+(F18*G18)+(F19*G19)+(F21*G21)+(F22*G22)+(F23*G23)+(F24*G24)+(F25*G25)+(F26*G26)+(F27*G27)+(F28*G28)+(F29*G29)+(F30*G30)+(F31*G31)+(F32*G32)+(F33*G33)+(F34*G34)+(F35*G35)
A39: OUR LLM COST / MONTH (per agent) | B39: =(B6*H6)+(B7*H7)+(B8*H8)+(B10*H10)+(B11*H11)+(B12*H12)+(B13*H13)+(B14*H14)+(B15*H15)+(B16*H16)+(B17*H17)+(B18*H18)+(B19*H19)+(B21*H21)+(B22*H22)+(B23*H23)+(B24*H24)+(B25*H25)+(B26*H26)+(B27*H27)+(B28*H28)+(B29*H29)+(B30*H30)+(B31*H31)+(B32*H32)+(B33*H33)+(B34*H34)+(B35*H35) | C39: =(C6*H6)+(C7*H7)+(C8*H8)+(C10*H10)+(C11*H11)+(C12*H12)+(C13*H13)+(C14*H14)+(C15*H15)+(C16*H16)+(C17*H17)+(C18*H18)+(C19*H19)+(C21*H21)+(C22*H22)+(C23*H23)+(C24*H24)+(C25*H25)+(C26*H26)+(C27*H27)+(C28*H28)+(C29*H29)+(C30*H30)+(C31*H31)+(C32*H32)+(C33*H33)+(C34*H34)+(C35*H35) | D39: =(D6*H6)+(D7*H7)+(D8*H8)+(D10*H10)+(D11*H11)+(D12*H12)+(D13*H13)+(D14*H14)+(D15*H15)+(D16*H16)+(D17*H17)+(D18*H18)+(D19*H19)+(D21*H21)+(D22*H22)+(D23*H23)+(D24*H24)+(D25*H25)+(D26*H26)+(D27*H27)+(D28*H28)+(D29*H29)+(D30*H30)+(D31*H31)+(D32*H32)+(D33*H33)+(D34*H34)+(D35*H35) | E39: =(E6*H6)+(E7*H7)+(E8*H8)+(E10*H10)+(E11*H11)+(E12*H12)+(E13*H13)+(E14*H14)+(E15*H15)+(E16*H16)+(E17*H17)+(E18*H18)+(E19*H19)+(E21*H21)+(E22*H22)+(E23*H23)+(E24*H24)+(E25*H25)+(E26*H26)+(E27*H27)+(E28*H28)+(E29*H29)+(E30*H30)+(E31*H31)+(E32*H32)+(E33*H33)+(E34*H34)+(E35*H35) | F39: =(F6*H6)+(F7*H7)+(F8*H8)+(F10*H10)+(F11*H11)+(F12*H12)+(F13*H13)+(F14*H14)+(F15*H15)+(F16*H16)+(F17*H17)+(F18*H18)+(F19*H19)+(F21*H21)+(F22*H22)+(F23*H23)+(F24*H24)+(F25*H25)+(F26*H26)+(F27*H27)+(F28*H28)+(F29*H29)+(F30*H30)+(F31*H31)+(F32*H32)+(F33*H33)+(F34*H34)+(F35*H35)
A40: MARGIN / MONTH (per agent) | B40: =B38-B39 | C40: =C38-C39 | D40: =D38-D39 | E40: =E38-E39 | F40: =F38-F39
A41: MARGIN % (per agent) | B41: =B40/B38 | C41: =C40/C38 | D41: =D40/D38 | E41: =E40/E38 | F41: =F40/F38

Sheet Assumptions
A1: Parameter | B1: Value | C1: Source / Rationale
A3: UPFRONT COSTS (One-Time)
A4: Pty Ltd Registration (ASIC) | B4: 576 | C4: Source: register.business.gov.au, 2026
A5: Director ID Application | B5: 0 | C5: Free via abrs.gov.au
A6: Business Name Registration (3yr) | B6: 98 | C6: Source: ASIC, $42/yr or $98/3yr
A7: Legal Review (Terms + Privacy) | B7: 3500 | C7: Estimate: Australian technology lawyer, 2026
A8: PI + Cyber Insurance (Year 1) | B8: 1500 | C8: Source: Startupcover/BizCover, $900-$2,000 range. Midpoint used.
A9: Domain (sagereasoning.com) - already owned | B9: 0 | C9: Already purchased
A10: Stripe Setup | B10: 0 | C10: Free to set up; per-transaction fees apply
A11: TOTAL UPFRONT INVESTMENT | B11: =SUM(B4:B10)
A13: MONTHLY FIXED COSTS
A14: Vercel Hosting (Pro) | B14: 20 | C14: Source: vercel.com pricing, 2026
A15: Supabase (Pro) | B15: 25 | C15: Source: supabase.com pricing, 2026
A16: Accounting Software (Xero) | B16: 29 | C16: Source: xero.com.au, Starter plan
A17: Insurance (amortised monthly) | B17: 125 | C17: $1,500/12. Conservative midpoint.
A18: ASIC Annual Fee (amortised monthly) | B18: 48 | C18: $576/12
A19: Domain Renewal (amortised monthly) | B19: 2 | C19: ~$20/year
A20: Email Service (Resend/Buttondown) | B20: 0 | C20: Free tier sufficient initially
A21: Miscellaneous/Buffer | B21: 30 | C21: Contingency for minor costs
A22: TOTAL MONTHLY FIXED COSTS | B22: =SUM(B14:B21)
A24: PRICING MODEL (Half-Competitor Rule — replaces flat 2× R5)
A25: Pricing principle | B25: ½ × lowest competitor | C25: Half the lowest range price in each comparable category
A26: Enrichment benchmark (Clearbit) | B26: $0.36/lookup | C26: Most skills priced at $0.18 = half Clearbit
A27: Assessment benchmark (Crystal Knows) | B27: Est. $1-5/profile | C27: sage-diagnose, sage-profile at $0.50 = half of $1
A28: Guardrail benchmark (Guardrails AI) | B28: $0.005/check | C28: sage-guard at $0.0025 = half of $0.005
A29: R5 still satisfied? | B29: YES | C29: All prices exceed 2× LLM cost. Margins now 60-93% instead of flat 50%.
A30: Avg margin % across product surface | B30: 89.3% | C30: Weighted higher than old 50% due to pricing above minimum R5
A32: SUBSCRIPTION PRICING
A33: Prokoptos subscription (monthly) | B33: 7 | C33: $7/month or $60/year
A34: Prokoptos subscription (annual) | B34: 60 | C34: Save $24 vs monthly
A35: Stripe fee per transaction | B35: =B32-(0.0175*B32+0.30) | C35: Source: stripe.com.au, 2026
A36: Net revenue per Prokoptos sub (monthly, after Stripe)
A38: CONVERSION & GROWTH ASSUMPTIONS
A39: Free-to-Paid conversion (human Prokoptos) | B39: 0.05 | C39: 5% conservative. Industry SaaS freemium: 2-5%. Niche = higher intent.
A40: Agent free-to-paid conversion | B40: 0.08 | C40: 8%. Free foundational check → CTA → upgrade.
A41: Monthly human user growth rate | B41: 30-50% | C41: Slowing: 150% M1, tapering to 17% by M12.
A42: Monthly agent developer growth rate | B42: 20-40% | C42: MCP registry discovery, API directories.
A43: Patron contribution rate (free users) | B43: 0.005 | C43: 0.5% of free users contribute ~$3/mo avg
A45: AGENT MIX ASSUMPTIONS (Month 12 Base Case)
A46: Reasoning Guard agents (paid) | B46: 3 | C46: High-volume gate pattern.
...

Sheet 12-Month Projection
B1: Month 1 | C1: Month 2 | D1: Month 3 | E1: Month 4 | F1: Month 5 | G1: Month 6 | H1: Month 7 | I1: Month 8 | J1: Month 9 | K1: Month 10 | L1: Month 11 | M1: Month 12 | N1: TOTAL
A3: USER GROWTH (Cumulative)
A4: Registered Human Users | B4: 20 | C4: 50 | D4: 100 | E4: 170 | F4: 260 | G4: 370 | H4: 500 | I4: 650 | J4: 820 | K4: 1000 | L4: 1200 | M4: 1400
A5: Agent Developers Registered | B5: 5 | C5: 12 | D5: 25 | E5: 40 | F5: 60 | G5: 85 | H5: 115 | I5: 150 | J5: 190 | K5: 235 | L5: 285 | M5: 340
A7: PAID AGENTS BY TYPE
A8: Reasoning Guard agents | B8: 0 | C8: 0 | D8: 0 | E8: 1 | F8: 1 | G8: 1 | H8: 2 | I8: 2 | J8: 2 | K8: 3 | L8: 3 | M8: 3
A9: Decision Support agents | B9: 0 | C9: 0 | D9: 1 | E9: 1 | F9: 2 | G9: 3 | H9: 4 | I9: 5 | J9: 6 | K9: 7 | L9: 7 | M9: 8
A10: Compliance agents | B10: 0 | C10: 0 | D10: 0 | E10: 0 | F10: 0 | G10: 1 | H10: 1 | I10: 1 | J10: 2 | K10: 2 | L10: 3 | M10: 3
A11: Personal Coach agents | B11: 0 | C11: 0 | D11: 0 | E11: 1 | F11: 1 | G11: 2 | H11: 2 | I11: 3 | J11: 4 | K11: 4 | L11: 5 | M11: 6
A12: Full-Stack agents | B12: 0 | C12: 0 | D12: 0 | E12: 0 | F12: 1 | G12: 1 | H12: 2 | I12: 2 | J12: 3 | K12: 3 | L12: 4 | M12: 5
A13: Total Paid Agents | B13: =SUM(B8:B12) | C13: =SUM(C8:C12) | D13: =SUM(D8:D12) | E13: =SUM(E8:E12) | F13: =SUM(F8:F12) | G13: =SUM(G8:G12) | H13: =SUM(H8:H12) | I13: =SUM(I8:I12) | ... M13: =SUM(M8:M12)
A14: Prokoptos Subscribers (5% of humans) | B14: =B4*0.05 | C14: =C4*0.05 | D14: =D4*0.05 | E14: =E4*0.05 | F14: =F4*0.05 | G14: =G4*0.05 | H14: =H4*0.05 | I14: =I4*0.05 | ... M14: =M4*0.05
A16: REVENUE
A17: Prokoptos Subscription Revenue | B17: =ROUND(B14,0)*Assumptions!B32 | C17: =ROUND(C14,0)*Assumptions!B32 | D17: =ROUND(D14,0)*Assumptions!B32 | E17: =ROUND(E14,0)*Assumptions!B32 | F17: =ROUND(F14,0)*Assumptions!B32 | G17: =ROUND(G14,0)*Assumptions!B32 | H17: =ROUND(H14,0)*Assumptions!B32 | I17: =ROUND(I14,0)*Assumptions!B32 | J17: =ROUND(J14,0)*Assumptions!B32 | K17: =ROUND(K14,0)*Assumptions!B32 | L17: =ROUND(L14,0)*Assumptions!B32 | M17: =ROUND(M14,0)*Assumptions!B32
A18: Guard API Revenue ($120.50/agent/mo) | B18: =B8*120.5 | C18: =C8*120.5 | D18: =D8*120.5 | E18: =E8*120.5 | F18: =F8*120.5 | G18: =G8*120.5 | H18: =H8*120.5 | I18: =I8*120.5 | ... M18: =M8*120.5
A19: Decision Support API Revenue ($384.90/agent/mo) | B19: =B9*384.9 | C19: =C9*384.9 | D19: =D9*384.9 | E19: =E9*384.9 | F19: =F9*384.9 | G19: =G9*384.9 | H19: =H9*384.9 | I19: =I9*384.9 | ... M19: =M9*384.9
A20: Compliance API Revenue ($438.30/agent/mo) | B20: =B10*438.3 | C20: =C10*438.3 | D20: =D10*438.3 | E20: =E10*438.3 | F20: =F10*438.3 | G20: =G10*438.3 | H20: =H10*438.3 | I20: =I10*438.3 | ... M20: =M10*438.3
A21: Coach API Revenue ($334.85/agent/mo) | B21: =B11*334.85 | C21: =C11*334.85 | D21: =D11*334.85 | E21: =E11*334.85 | F21: =F11*334.85 | G21: =G11*334.85 | H21: =H11*334.85 | I21: =I11*334.85 | ... M21: =M11*334.85
A22: Full-Stack API Revenue ($470.55/agent/mo) | B22: =B12*470.55 | C22: =C12*470.55 | D22: =D12*470.55 | E22: =E12*470.55 | F22: =F12*470.55 | G22: =G12*470.55 | H22: =H12*470.55 | I22: =I12*470.55 | ... M22: =M12*470.55
A23: Human Free-Tier Scoring Revenue | B23: 0 | C23: 0 | D23: 0 | E23: 0 | F23: 0 | G23: 0 | H23: 0 | I23: 0 | J23: 0 | K23: 0 | L23: 0 | M23: 0
A24: Patronage Revenue | B24: 1 | C24: 2 | D24: 3 | E24: 5 | F24: 8 | G24: 11 | H24: 15 | I24: 20 | J24: 25 | K24: 30 | L24: 36 | M24: 42
A25: Badges / Accessories (net) | B25: 0 | C25: 0 | D25: 0 | E25: 45 | F25: 60 | G25: 80 | H25: 100 | I25: 120 | J25: 140 | K25: 150 | L25: 160 | M25: 180
A26: Enterprise Licensing | B26: 0 | C26: 0 | D26: 0 | E26: 0 | F26: 0 | G26: 0 | H26: 0 | I26: 0 | J26: 500 | K26: 500 | L26: 500 | M26: 500
A27: TOTAL MONTHLY REVENUE | B27: =SUM(B17:B26) | C27: =SUM(C17:C26) | D27: =SUM(D17:D26) | E27: =SUM(E17:E26) | F27: =SUM(F17:F26) | G27: =SUM(G17:G26) | H27: =SUM(H17:H26) | I27: =SUM(I17:I26) | ... M27: =SUM(M17:M26) | N27: =SUM(B27:M27)
A29: COSTS
A30: Monthly Fixed Costs | B30: =Assumptions!B22 | C30: =Assumptions!B22 | D30: =Assumptions!B22 | E30: =Assumptions!B22 | F30: =Assumptions!B22 | G30: =Assumptions!B22 | H30: =Assumptions!B22 | I30: =Assumptions!B22 | J30: =Assumptions!B22 | K30: =Assumptions!B22 | L30: =Assumptions!B22 | M30: =Assumptions!B22
A31: LLM API Costs — Paid Agents (actual LLM cost) | B31: =B8*12.4+B9*37.47+B10*43.81+B11*33.99+B12*46.62 | C31: =C8*12.4+C9*37.47+C10*43.81+C11*33.99+C12*46.62 | D31: =D8*12.4+D9*37.47+D10*43.81+D11*33.99+D12*46.62 | E31: =E8*12.4+E9*37.47+E10*43.81+E11*33.99+E12*46.62 | F31: =F8*12.4+F9*37.47+F10*43.81+F11*33.99+F12*46.62 | G31: =G8*12.4+G9*37.47+G10*43.81+G11*33.99+G12*46.62 | H31: =H8*12.4+H9*37.47+H10*43.81+H11*33.99+H12*46.62 | I31: =I8*12.4+I9*37.47+I10*43.81+I11*33.99+I12*46.62 | ... M31: =M8*12.4+M9*37.47+M10*43.81+M11*33.99+M12*46.62
A32: API Costs — Free Tier (human + free agents) | B32: 15 | C32: 20 | D32: 30 | E32: 40 | F32: 50 | G32: 60 | H32: 70 | I32: 80 | J32: 90 | K32: 100 | L32: 110 | M32: 120
A33: Stripe Transaction Fees (~2%) | B33: =B27*0.02 | C33: =C27*0.02 | D33: =D27*0.02 | E33: =E27*0.02 | F33: =F27*0.02 | G33: =G27*0.02 | H33: =H27*0.02 | I33: =I27*0.02 | ... M33: =M27*0.02
A34: TOTAL MONTHLY COSTS | B34: =B30+B31+B32+B33 | C34: =C30+C31+C32+C33 | D34: =D30+D31+D32+D33 | E34: =E30+E31+E32+E33 | F34: =F30+F31+F32+F33 | G34: =G30+G31+G32+G33 | H34: =H30+H31+H32+H33 | I34: =I30+I31+I32+I33 | ... M34: =M30+M31+M32+M33 | N34: =SUM(B34:M34)
A36: NET POSITION
A37: Monthly Net (Revenue - Costs) | B37: =B27-B34 | C37: =C27-C34 | D37: =D27-D34 | E37: =E27-E34 | F37: =F27-F34 | G37: =G27-G34 | H37: =H27-H34 | I37: =I27-I34 | ... M37: =M27-M34 | N37: =SUM(B37:M37)
A38: Cumulative Net (incl. upfront costs) | B38: =-Assumptions!B11+B37 | C38: =B38+C37 | D38: =C38+D37 | E38: =D38+E37 | F38: =E38+F37 | G38: =F38+G37 | H38: =G38+H37 | I38: =H38+I37 | J38: =I38+J37 | ... M38: =L38+M37
A40: MARGIN ANALYSIS (Revised Pricing)
A41: API revenue as % of total | B41: =IF(B27=0,0,(B18+B19+B20+B21+B22)/B27) | C41: =IF(C27=0,0,(C18+C19+C20+C21+C22)/C27) | D41: =IF(D27=0,0,(D18+D19+D20+D21+D22)/D27) | E41: =IF(E27=0,0,(E18+E19+E20+E21+E22)/E27) | F41: =IF(F27=0,0,(F18+F19+F20+F21+F22)/F27) | G41: =IF(G27=0,0,(G18+G19+G20+G21+G22)/G27) | H41: =IF(H27=0,0,(H18+H19+H20+H21+H22)/H27) | I41: =IF(I27=0,0,(I18+I19+I20+I21+I22)/I27) | ... M41: =IF(M27=0,0,(M18+M19+M20+M21+M22)/M27)
A42: Blended API margin % (was 50%, now higher) | B42: =IF((B18+B19+B20+B21+B22)=0,0,1-B31/(B18+B19+B20+B21+B22)) | C42: =IF((C18+C19+C20+C21+C22)=0,0,1-C31/(C18+C19+C20+C21+C22)) | D42: =IF((D18+D19+D20+D21+D22)=0,0,1-D31/(D18+D19+D20+D21+D22)) | E42: =IF((E18+E19+E20+E21+E22)=0,0,1-E31/(E18+E19+E20+E21+E22)) | F42: =IF((F18+F19+F20+F21+F22)=0,0,1-F31/(F18+F19+F20+F21+F22)) | G42: =IF((G18+G19+G20+G21+G22)=0,0,1-G31/(G18+G19+G20+G21+G22)) | H42: =IF((H18+H19+H20+H21+H22)=0,0,1-H31/(H18+H19+H20+H21+H22)) | I42: =IF((I18+I19+I20+I21+I22)=0,0,1-I31/(I18+I19+I20+I21+I22)) | ... M42: =IF((M18+M19+M20+M21+M22)=0,0,1-M31/(M18+M19+M20+M21+M22))

Sheet Break-Even Analysis
A1: Break-Even Analysis — Revised Half-Competitor Pricing
A3: Break-Even Metric | B3: Value | C3: Explanation
A5: SCENARIO A: Prokoptos Only (No API Revenue)
A6: Monthly fixed costs | B6: =Assumptions!B22
A7: Net revenue per Prokoptos sub (after Stripe) | B7: =Assumptions!B35
A8: Subscribers needed to break even | B8: =ROUNDUP(B6/B7,0) | C8: Hardest path. Prokoptos alone.
A9: Registered users needed (at 5% conversion) | B9: =B8*20
A11: SCENARIO B: Mixed Model (5 Decision Support Agents + Prokoptos)
A12: Monthly API margin from 5 Decision agents | B12: =5*347.43 | C12: 5 agents × $347.43 margin/agent/mo
A13: Remaining fixed costs after API margin | B13: =B6-B12
A14: Additional Prokoptos subs needed | B14: =IF(B13<=0,0,ROUNDUP(B13/B7,0))
A15: Registered users needed | B15: =B14*20
A17: SCENARIO C: Diverse Agent Mix (Month 12 Base Case)
A18: Guard agents (3) margin/mo | B18: =3*108.1 | C18: 3 × $108.10/agent/mo
A19: Decision agents (8) margin/mo | B19: =8*347.43 | C19: 8 × $347.43/agent/mo
A20: Compliance agents (3) margin/mo | B20: =3*394.49 | C20: 3 × $394.49/agent/mo
A21: Coach agents (6) margin/mo | B21: =6*300.86 | C21: 6 × $300.86/agent/mo
A22: Full-stack agents (5) margin/mo | B22: =5*423.93 | C22: 5 × $423.93/agent/mo
A23: Total API margin (25 agents) | B23: =SUM(B18:B22)
A24: Fixed costs covered? | B24: =IF(B23>=B6,"YES — API alone covers fixed costs","NO")
A25: Surplus after fixed costs | B25: =B23-B6 | C25: Available for growth reinvestment.
A27: SCENARIO D: API Revenue Only (No Prokoptos)
A28: Weighted avg margin per call | B28: =0.0974 | C28: Weighted across agent mix
A29: API calls/month to cover fixed costs | B29: =ROUNDUP(B6/B28,0)
A31: PAYBACK PERIOD ON UPFRONT INVESTMENT
A32: Total upfront investment | B32: =Assumptions!B11
A33: Month 12 monthly net (from projection) | C33: See 12-Month Projection sheet

Sheet Scenario Analysis
B1: Bear Case | C1: Base Case | D1: Bull Case | E1: Notes
A3: 12-MONTH END STATE
A4: Registered Human Users | B4: 600 | C4: 1400 | D4: 3000
A5: Agent Developers Registered | B5: 80 | C5: 340 | D5: 800
A6: Human Conversion Rate | B6: 0.03 | C6: 0.05 | D6: 0.1
A7: Agent Conversion Rate | B7: 0.04 | C7: 0.08 | D7: 0.15
A9: PAID AGENT MIX (Month 12)
A10: Reasoning Guard agents | B10: 1 | C10: 3 | D10: 8
A11: Decision Support agents | B11: 2 | C11: 8 | D11: 20
A12: Compliance agents | B12: 0 | C12: 3 | D12: 10
A13: Personal Coach agents | B13: 1 | C13: 6 | D13: 15
A14: Full-Stack agents | B14: 0 | C14: 5 | D14: 12
A15: Total Paid Agents | B15: =SUM(B9:B13) | C15: =SUM(C9:C13) | D15: =SUM(D9:D13)
A17: MONTH 12 REVENUE (MONTHLY) — REVISED PRICING
A18: Prokoptos Subscribers | B18: =B3*B5 | C18: =C3*C5 | D18: =D3*D5
A19: Prokoptos Revenue/mo | B19: =B17*7 | C19: =C17*7 | D19: =D17*7
A21: Agent API Revenue/mo (NEW PRICES)
A22: Guard rev ($120.50/agent) | B22: =B9*120.5 | C22: =C9*120.5 | D22: =D9*120.5 | E22: Was $24.80
A23: Decision rev ($384.90/agent) | B23: =B10*384.9 | C23: =C10*384.9 | D23: =D10*384.9 | E23: Was $74.94
A24: Compliance rev ($438.30/agent) | B24: =B11*438.3 | C24: =C11*438.3 | D24: =D11*438.3 | E24: Was $87.63
A25: Coach rev ($334.85/agent) | B25: =B12*334.85 | C25: =C12*334.85 | D25: =D12*334.85 | E25: Was $67.97
A26: Full-stack rev ($470.55/agent) | B26: =B13*470.55 | C26: =C13*470.55 | D26: =D13*470.55 | E26: Was $93.23
A27: Total Agent API Revenue/mo | B27: =SUM(B21:B25) | C27: =SUM(C21:C25) | D27: =SUM(D21:D25)
A28: Other Revenue (patronage + badges + enterprise) | B28: 50 | C28: 350 | D28: 1500
A29: TOTAL MONTH 12 REVENUE | B29: =B18+B26+B27 | C29: =C18+C26+C27 | D29: =D18+D26+D27
A31: MONTH 12 COSTS (MONTHLY)
A32: Fixed Costs/mo | B32: =Assumptions!B22 | C32: =Assumptions!B22 | D32: =Assumptions!B22
A33: LLM Costs (actual, not 50%)
A34: Guard LLM ($12.40/agent) | B34: =B9*12.4 | C34: =C9*12.4 | D34: =D9*12.4
A35: Decision LLM ($37.47/agent) | B35: =B10*37.47 | C35: =C10*37.47 | D35: =D10*37.47
A36: Compliance LLM ($43.81/agent) | B36: =B11*43.81 | C36: =C11*43.81 | D36: =D11*43.81
A37: Coach LLM ($33.99/agent) | B37: =B12*33.99 | C37: =C12*33.99 | D37: =D12*33.99
A38: Full-stack LLM ($46.62/agent) | B38: =B13*46.62 | C38: =C13*46.62 | D38: =D13*46.62
A39: Total LLM Costs | B39: =SUM(B33:B37) | C39: =SUM(C33:C37) | D39: =SUM(D33:D37)
A40: Free Tier Costs | B40: 50 | C40: 120 | D40: 200
A41: Stripe Fees (~2%) | B41: =B28*0.02 | C41: =C28*0.02 | D41: =D28*0.02
A42: TOTAL MONTH 12 COSTS | B42: =B31+B38+B39+B40 | C42: =C31+C38+C39+C40 | D42: =D31+D38+D39+D40
A44: VERDICTS
A45: Month 12 Net (Revenue - Costs) | B45: =B28-B41 | C45: =C28-C41 | D45: =D28-D41
A46: Annualised Run Rate (Month 12 × 12) | B46: =B44*12 | C46: =C44*12 | D46: =D44*12
...

Sheet Pricing Comparison
A1: Old vs New Pricing — Impact on Revenue per Agent
A3: Agent Archetype | B3: Old Rev/mo | C3: New Rev/mo | D3: Revenue Change | E3: Old Cost/mo | F3: New Cost/mo | G3: Old Margin | H3: New Margin | I3: Old Margin % | J3: New Margin %
A4: Reasoning Guard | B4: 24.8 | C4: 120.5 | D4: =C4/B4-1 | E4: 12.4 | F4: 12.4 | G4: =B4-E4 | H4: =C4-F4 | I4: =G4/B4 | J4: =H4/C4
A5: Decision Support | B5: 74.94 | C5: 384.9 | D5: =C5/B5-1 | E5: 37.47 | F5: 37.47 | G5: =B5-E5 | H5: =C5-F5 | I5: =G5/B5 | J5: =H5/C5
A6: Compliance Agent | B6: 87.63 | C6: 438.3 | D6: =C6/B6-1 | E6: 43.82 | F6: 43.81 | G6: =B6-E6 | H6: =C6-F6 | I6: =G6/B6 | J6: =H6/C6
A7: Personal Coach | B7: 67.97 | C7: 334.85 | D7: =C7/B7-1 | E7: 33.99 | F7: 33.99 | G7: =B7-E7 | H7: =C7-F7 | I7: =G7/B7 | J7: =H7/C7
A8: Full-Stack Agent | B8: 93.23 | C8: 470.55 | D8: =C8/B8-1 | E8: 46.62 | F8: 46.62 | G8: =B8-E8 | H8: =C8-F8 | I8: =G8/B8 | J8: =H8/C8

Sheet Mythos Cost Scenario
A1: Mythos Cost Impact — Half-Competitor Pricing Model
A2: Under half-competitor pricing, Mythos increases LLM cost but customer price stays anchored to competitor benchmarks.
A4: Agent Archetype | B4: Current Rev/mo | C4: Current LLM Cost/mo | D4: Current Margin | E4: Mythos LLM Cost/mo (×2.08) | F4: Mythos Margin | G4: Margin % Change
A5: Reasoning Guard | B5: 120.5 | C5: 12.4 | D5: =B5-C5 | E5: =C5*2.08 | F5: =B5-E5 | G5: =F5/D5-1
A6: Decision Support | B6: 384.9 | C6: 37.47 | D6: =B6-C6 | E6: =C6*2.08 | F6: =B6-E6 | G6: =F6/D6-1
A7: Compliance Agent | B7: 438.3 | C7: 43.81 | D7: =B7-C7 | E7: =C7*2.08 | F7: =B7-E7 | G7: =F7/D7-1
A8: Personal Coach | B8: 334.85 | C8: 33.99 | D8: =B8-C8 | E8: =C8*2.08 | F8: =B8-E8 | G8: =F8/D8-1
A9: Full-Stack Agent | B9: 470.55 | C9: 46.62 | D9: =B9-C9 | E9: =C9*2.08 | F9: =B9-E9 | G9: =F9/D9-1
A12: KEY INSIGHT
A13: Under half-competitor pricing, Mythos compresses margins but they remain well above R5 minimum.
A14: Customer prices are anchored to competitors, NOT to LLM cost. This is a strategic advantage:
A15: if competitors also face higher costs, their prices rise and our half-competitor anchor rises too.
